{
 "cells": [
  {
   "cell_type": "markdown",
   "metadata": {},
   "source": [
    "## এই সেকশনে থাকছে   \n",
    "\n",
    "* [এক্সেপশন](exception.md)\n",
    "* [এক্সেপশন হ্যান্ডেলিং](exception-handling.md)\n",
    "* [finally](finally.md)\n",
    "* [এক্সেপশন Raise](raise-exception.md)\n",
    "* [Assertions](assertions.md)"
   ]
  },
  {
   "cell_type": "markdown",
   "metadata": {},
   "source": [
    "## এক্সেপশন   \n",
    "\n",
    "এটি এমন একটি ইভেন্ট যা ঘটে তখনই, যখন একটি প্রোগ্রামের স্বাভাবিক এক্সিকিউশনের মধ্যে কোন বাধার উৎপত্তি হয়। অর্থাৎ যখন একটি পাইথন স্ক্রিপ্ট এমন কোন একটি সমস্যাপূর্ণ অবস্থার সম্মুখীন হয় যা সে এড়িয়ে যেতে পারে না অথবা সমাধান করতে পারে না অতঃপর প্রোগ্রামের এক্সিকিউশন বন্ধ হয়ে যায় - সেরকম ঘটনাকে এক্সেপশন বলা হয়। এক্সেপশন এর আভিধানিক অর্থ থেকেও বোঝা যায় যে ব্যতিক্রম কোন অবস্থার উৎপত্তি।   \n",
    "\n",
    "সাধারণত ভুল কোড বা ইনপুটের জন্য প্রোগ্রামের মধ্যে এক্সেপশন তৈরি হয় যা সঠিকভাবে হ্যান্ডেল না করলে প্রোগ্রাম অনাকাঙ্ক্ষিত ভাবে বন্ধ হয়ে যেতে পারে। একটি উদাহরণ দিয়ে আমারা বোঝার চেষ্টা করি - \n",
    "\n",
    "```python\n",
    "a = 2500\n",
    "b = 0\n",
    "\n",
    "print(a/b)\n",
    "print(\"I did it\")\n",
    "```  \n",
    "\n",
    "আউটপুট, \n",
    "\n",
    "```python\n",
    "Traceback (most recent call last):\n",
    "  File \"<stdin>\", line 1, in <module>\n",
    "ZeroDivisionError: division by zero\n",
    "```  \n",
    "\n",
    "উপরের প্রোগ্রামে, গণিতের নিয়ম অনুযায়ী `a` কে `b` দিয়ে ভাগ করা সম্ভব না আর তাই যখনই  `print(a/b)` স্টেটমেন্টটি এক্সিকিউট হতে চেয়েছে তখনি এক ধরণের ব্যতিক্রম অবস্থার উৎপত্তি হয়েছে যাকে এক্সেপশন বলা হচ্ছে। আর তাই পাইথন ওই প্রোগ্রামের পরবর্তী স্টেটমেন্ট গুলো এক্সিকিউট না করে বরং প্রোগ্রাম এক্সিকিউশন বন্ধ করে দিয়েছে। কিন্তু দেখা যাচ্ছে কোডের লেখায় বা নিয়মে কিন্তু কোন ভুল নাই। শুধুমাত্র রান টাইমেই এই পরিস্থিতি তৈরি হয়েছে। তাই এরকম অবস্থায় পাইথন এক্সেপশন তৈরি করে।  \n",
    "\n",
    "প্রোগ্রামের মধ্যে বিভিন্ন কারনে বিভিন্ন রকম exception তৈরি হয়। কিছু কিছু নির্দিষ্ট কারণের জন্য ঘটা অনাকাঙ্ক্ষিত অবস্থা গুলোর সাপেক্ষে পাইথনে অনেক এক্সেপশন আছে। নিচে কয়েকটি উল্লেখ করা হলঃ  \n",
    "\n",
    "<table class=\"table table-bordered\">\n",
    "<tbody><tr>\n",
    "<th><b>এক্সেপশনের নাম</b></th>\n",
    "<th><b>বর্ণনা</b></th>\n",
    "</tr>\n",
    "<tr>\n",
    "<td>Exception</td>\n",
    "<td>সব রকম এক্সেপশনের বেজ ক্লাস</td>\n",
    "</tr>\n",
    "<tr>\n",
    "<td>StopIteration</td>\n",
    "<td>যখন একটি ইটারেটরের next() মেথডটি কোন অবজেক্টকে পয়েন্ট করে না</td>\n",
    "</tr>\n",
    "<tr>\n",
    "<td>ArithmeticError</td>\n",
    "<td>নিউমেরিক ক্যালকুলেশনের জন্য তৈরি হয় এমন এক্সেপশনের বেজ ক্লাস</td>\n",
    "</tr>\n",
    "<tr>\n",
    "<td>OverflowError</td>\n",
    "<td>যখন একটি নিউমেরিক টাইপের ম্যাক্সিমাম লিমিট অতিক্রম করে</td>\n",
    "</tr>\n",
    "<tr>\n",
    "<td>ZeroDivisonError</td>\n",
    "<td>যখন শূন্য দিয়ে ভাগের ঘটনা ঘটে</td>\n",
    "</tr>\n",
    "<tr>\n",
    "<td>ImportError</td>\n",
    "<td>যখন import স্টেটমেন্ট ফেইল করে অর্থাৎ কোন কারনে import সম্পন্ন হয় না</td>\n",
    "</tr>\n",
    "<tr>\n",
    "<td><p>IndexError</p><p>KeyError</p></td>\n",
    "<td><p>যখন একটি সিকোয়েন্স টাইপ অবজেক্টে চাহিদা মোতাবেক ইনডেক্স পাওয়া যায় না</p></td>\n",
    "</tr>\n",
    "<tr>\n",
    "<td>NameError</td>\n",
    "<td>যখন নির্দিষ্ট নামের কোন আইডেন্টিফায়ারকে লোকাল বা গ্লোবাল স্কোপে খুঁজে পাওয়া যায় না</td>\n",
    "</tr>\n",
    "<tr>\n",
    "<td><p>IOError</p></td>\n",
    "<td><p>যখন ইনপুট বা আউটপুট সম্পর্কিত কোন অপারেশন সফল হয় না যেমন ফাইল থেকে পড়ার জন্য ওপেন ফাংশন কাজ করতে না পারলে</p></td>\n",
    "</tr>\n",
    "<tr>\n",
    "<td><p>SyntaxError</p><p>IndentationError</p></td>\n",
    "<td><p>পাইথন প্রোগ্রাম লেখার সময় ভুল কোন কি-ওয়ার্ড বা স্টেটমেন্ট থাকলে</p></td>\n",
    "</tr>\n",
    "<tr>\n",
    "<td>RuntimeError</td>\n",
    "<td>যখন কোন একটি এক্সেপশন ঘটে যা পাইথনের নির্দিষ্ট কোন ক্যাটাগরির এক্সেপশনের মধ্যেই পরে না</td>\n",
    "</tr>\n",
    "</tbody></table>\n"
   ]
  },
  {
   "cell_type": "markdown",
   "metadata": {},
   "source": [
    "## এক্সেপশন হ্যান্ডেলিং  \n",
    "\n",
    "আগের চ্যাপ্টারে আমরা দেখেছি, এক্সেপশন তৈরি হলে প্রোগ্রাম অনাকাঙ্ক্ষিত ভাবে বন্ধ হয়ে যায়। খুশির খবর হচ্ছে এরকম তৈরি হওয়া এক্সেপশন গুলোকে সঠিকভাবে হ্যান্ডেল করতে পারলে প্রোগ্রাম যেমন বন্ধ না হয়ে এগিয়ে চলবে তেমনি প্রোগ্রামের কোথায় কোন সমস্যা আছে সেগুলোকেও সহজে চিহ্নিত করা যাবে। এ জন্য পাইথনে আছে `try`, `except` স্টেটমেন্টের ব্যবহার।   \n",
    "\n",
    "`try` ব্লকের মধ্যে এমন কোড গুলো লেখা হয় যেখানে এক্সেপশন তৈরি হতে পারে (ইউজার ইনপুট বা সেরকম অন্যান্য কারনে)। আর `except` ব্লকের মধ্যে লেখা হয় এমন কোড যেগুলো এক্সিকিউট হবে যদি আসলেই ওই `try` ব্লকের মধ্যে কোন এক্সেপশন তৈরি হয়। অর্থাৎ `try` এর মধ্যে এক্সেপশন তৈরি হলে এই ব্লকের কোড এক্সিকিউশন বন্ধ হবে কিন্তু `except` ব্লকের কোড স্বাভাবিক ভাবে এক্সিকিউট হবে। একটি উদাহরণ দেখি -  \n",
    "\n",
    "```python\n",
    "try:\n",
    "\ta = 1000\n",
    "\tb = int(input(\"Enter a divisor to divide 1000: \"))\n",
    "\tprint(a/b)\n",
    "except ZeroDivisionError:\n",
    "\tprint(\"You entered 0 which is not permitted!\")\n",
    "```  \n",
    "\n",
    "যদি ইনপুট হয় নিচের মত, \n",
    "\n",
    "```python\n",
    "Enter a divisor to divide 1000: 5\n",
    "```\n",
    "\n",
    "তাহলে আউটপুট,  \n",
    "\n",
    "```python\n",
    "200.0\n",
    "```   \n",
    "\n",
    "অথবা যদি ইনপুট হয় এরকম, \n",
    "\n",
    "```python\n",
    "Enter a divisor to divide 1000: 0\n",
    "```\n",
    "\n",
    "তবে আউটপুট,  \n",
    "\n",
    "```python\n",
    "You entered 0 which is not permitted!\n",
    "```   \n",
    "\n",
    "উপরের প্রোগ্রামে দুটো নাম্বার নিয়ে ভাগের কাজ করা হয়েছে। একটি নাম্বারের মান 1000 এবং আরেকটি নিচ্ছি ইউজারের কাছ থেকে। যদি ইউজার ভালোয় ভালোয় সঠিক সংখ্যা ইনপুট দেয় (যেমন 5) তাহলে প্রোগ্রামটি সঠিক ভাবে কাজ করে ভাগফল প্রিন্ট করছে। কিন্তু ইউজারের মনোভাব তো আমরা জানি না। ইউজার চাইলে শূন্য ইনপুট দিতে পারে। আর তখন প্রোগ্রাম ভাগ করতে না পেরে অনাকাঙ্ক্ষিত ভাবে বন্ধ হয়ে যাবে।   \n",
    "\n",
    "আর তাই সেটুকু আন্দাজ করেই আমরা ভাগ করার কোড টুকু একটি ট্রাই ব্লকের মধ্যে লিখেছি এবং সেই ব্লকের মধ্যে যদি শূন্য দিয়ে ভাগ করার কারনে কোন এক্সেপশন তৈরি হয় তাহলে সেটা হ্যান্ডেল করার জন্য এক্সেপ্ট ব্লক ব্যবহার করেছি এবং নির্দিষ্ট করে `ZeroDivisionError` এক্সেপশন হ্যান্ডেল করেছি। এখন, ইউজার চাইলে শূন্য ইনপুট দিতে পারে, তাই বলে প্রোগ্রাম অনাকাঙ্ক্ষিত ভাবে শাটডাউন বা বন্ধ হবে না। বরং ইউজারকে যথাযথ ম্যাসেজ দেখিয়ে স্বাভাবিক কাজ চালিয়ে যেতে পারছে।   \n",
    "\n",
    "একটি `try` ব্লকের সাপেক্ষে একাধিক `except` ব্লক থাকতে পারে। আবার একটি `except` এর জন্য একাধিক এক্সেপশন ডিফাইন করা যেতে পারে ব্র্যাকেট এবং কমা ব্যবহার করে। এতে করে ট্রাই ব্লকের মধ্যে বিভিন্ন রকম এক্সেপশনের জন্য বিভিন্ন এক্সেপ্ট ব্লক দিয়ে সঠিক ভাবে সমস্যাকে চিহ্নিত করা যায় এবং সে অনুযায়ী কাজ করা যায়। আরেকটি উদাহরণ দেখি - \n",
    "\n",
    "```python\n",
    "try:\n",
    "    variable = 10\n",
    "    print(variable + \"hello\")\n",
    "    print(variable / 2)\n",
    "except ZeroDivisionError:\n",
    "    print(\"Divided by zero\")\n",
    "except (ValueError, TypeError):\n",
    "    print(\"Type or value error occurred\")\n",
    "```   \n",
    "\n",
    "আউটপুট,   \n",
    "\n",
    "```python\n",
    "Type or value error occurred\n",
    "```   \n",
    "\n",
    "উপরের প্রোগ্রামে ট্রাই ব্লকে দুই রকম অঘটন ঘটতে পারে। `variable` কে `2` দিয়ে ভাগ না করে শূন্য দিয়ে ভাগ করা হতে পারতো এবং সেক্ষেত্রে  `ZeroDivisionError` এক্সেপশন তৈরি হত। আবার ট্রাই ব্লকের দ্বিতীয় স্টেটমেন্ট যেখানে একটি ইন্টিজারের সাথে স্ট্রিং কে যোগ করে প্রিন্ট করার চেষ্টা করা হয়েছে, সেখানে। এই উদাহরণে এখানেই এক্সেপশন তৈরি হচ্ছে। আর তাই `TypeError` এক্সেপশন তৈরি হচ্ছে। কিন্তু আমরা সেটা সঠিকভাবে হ্যান্ডেল করেছি আর তাই প্রোগ্রাম হুট করে বন্ধ না হয়ে বরং সুন্দর ভাবে আমাদের নির্ধারিত একটি প্রিন্ট স্টেটমেন্ট `print(\"Type or value error occurred\")` এক্সিকিউট করেছে।   \n",
    "\n",
    "চাইলে সুনির্দিষ্ট ভাবে কোন এক্সেপশন ডিফাইন না করেও `except` ব্লক ব্যবহার করা যাবে। সেক্ষেত্রে `try` ব্লকের মধ্যে ঘটে যাওয়া যেকোনো রকম এক্সেপশনের জন্য এই `except` ব্লক রান করবে। যেমন - \n",
    "\n",
    "```python\n",
    "try:\n",
    "\tword = \"spam\"\n",
    "\tprint(word / 0)\n",
    "except:\n",
    "\tprint(\"An error occurred\")\n",
    "```   \n",
    "\n",
    "আউটপুট,   \n",
    "\n",
    "```python\n",
    "An error occurred\n",
    "```\n",
    "\n",
    "বোঝাই যাচ্ছে `try` ব্লকের মধ্যে উল্টা পাল্টা টাইপের ডাটা নিয়ে ভাগ করার কোড লেখা হয়েছে। রান টাইমে এখানে অবশ্যই এক্সেপশন তৈরি হচ্ছে। আর তাই `except` ব্লক ব্যবহার করে হ্যান্ডেলও করা হয়েছে। আপাত দৃষ্টিতে বিষয়টি ভালো মনে হলেও এভাবে হ্যান্ডেল করা ব্লকের মাধ্যমে ট্রাই ব্লকে ঘটে যাওয়া অঘটনের সঠিক কারণ চিহ্নিত করা যাবে না।   \n",
    "অর্থাৎ, ট্রাই  ব্লকে যেকোনো রকম সমস্যার জন্যই এই এক্সেপ্ট ব্লক এক্সিকিউট হবে এবং বার বার শুধু `An error occurred` ম্যাসেজটাই ইউজারকে দেখানো হবে। কিন্তু যদি সম্ভাবনাময় কয়েকটি নির্দিষ্ট টাইপের এক্সেপ্ট ব্লক লিখে সেগুলোর মধ্যে আলাদা আলাদা ম্যাসেজ প্রিন্ট করা হত। তাহলে ইউজারকে আরও সুনির্দিষ্ট ম্যাসেজ দেয়া যেত এবং প্রোগ্রামটিকে পরবর্তীতে আপডেট করতেও সুবিধা হত।   \n",
    "\n",
    ">  সংকলন - [নুহিল মেহেদী](https://nuhil.net) \n",
    "\n"
   ]
  },
  {
   "cell_type": "markdown",
   "metadata": {},
   "source": [
    "## ফাইনালি   \n",
    "\n",
    "যদি এমন দরকার হয় যে, যতই এক্সেপশন তৈরি হোক না কেন কিছু কোডকে রান করানো দরকার, তখন `finally` স্টেটমেন্ট ব্যবহার করা হয়। `try`, `except` ব্লকের নিচে `finally` ব্লক ব্যবহার করতে হয়। `try` বা `except` ব্লকের কোড রান হবার পর এই `finally` ব্লকের মধ্যে থাকা কোড গুলো রান হবেই। একটি উদাহরণ দেখি - \n",
    "\n",
    "```python\n",
    "try:\n",
    "   print(\"Hello\")\n",
    "   print(1 / 0)\n",
    "except ZeroDivisionError:\n",
    "   print(\"Divided by zero\")\n",
    "finally:\n",
    "   print(\"This code will run no matter what\")\n",
    "```  \n",
    "\n",
    "আউটপুট, \n",
    "\n",
    "```python\n",
    "Hello\n",
    "Divided by zero\n",
    "This code will run no matter what\n",
    "```   \n",
    "\n",
    "উপরের প্রোগ্রামে, `try` ব্লকের মধ্যে প্রথম প্রিন্ট স্টেটমেন্টের পর দ্বিতীয় প্রিন্ট স্টেটমেন্টে শূন্য দিয়ে ভাগের চেষ্টার কারনে `ZeroDivisionError` এক্সেপশন তৈরি হচ্ছে। সেটাকে সঠিকভাবে হ্যান্ডেল করায় `except` ব্লকের মধ্যে থাকা `print(\"Divided by zero\")` এক্সিকিউট করছে। এবং পরিশেষে, যেহেতু ঘটনা যাই হোক `finally` ব্লক এর কোড এক্সিকিউট হবেই, তাই `print(\"This code will run no matter what\")` স্টেটমেন্টটিও কাজ করছে।   \n",
    "\n",
    "যদি `finally` ব্লকের আগে এমন কোন এক্সেপশন তৈরি হয় যাকে সঠিক ভাবে হ্যান্ডেল করা হয় নাই, সে অবস্থাতেও `finally` ব্লকের কোড রান হবে। যেমন -  \n",
    "\n",
    "```python\n",
    "try:\n",
    "   print(1)\n",
    "   print(10 / 0)\n",
    "except ZeroDivisionError:\n",
    "   print(unknown_var)\n",
    "finally:\n",
    "   print(\"This is executed last\")\n",
    "```   \n",
    "\n",
    "আউটপুট,  \n",
    "\n",
    "```python\n",
    "1\n",
    "This is executed last\n",
    "Traceback (most recent call last):\n",
    "  File \"/Users/nuhil/Documents/Python/Test.py\", line 3, in <module>\n",
    "    print(10 / 0)\n",
    "ZeroDivisionError: division by zero\n",
    "\n",
    "During handling of the above exception, another exception occurred:\n",
    "\n",
    "Traceback (most recent call last):\n",
    "  File \"/Users/nuhil/Documents/Python/Test.py\", line 5, in <module>\n",
    "    print(unknown_var)\n",
    "NameError: name 'unknown_var' is not defined\n",
    "```   \n",
    "উপরের প্রোগ্রামের `try` ব্লকের মধ্যে একটি এক্সেপশন তৈরি হয় এবং সেটা `except` ব্লকে হ্যান্ডেল করা হয়। কিন্তু সেই হ্যান্ডেল করার ব্লকের মধ্যে আবার এমন একটা ভ্যারিয়েবল প্রিন্ট করতে চাওয়া হয়েছে যাকে ডিফাইন করাই হয় নাই। আর তাতে করে সেখানে একটা `NameError` টাইপের এক্সেপশন তৈরি হয় (যদিও এটাকে হ্যান্ডেল করা হয় নি)। তারপরেও `finally` ব্লক কাজ করছে আর তাই `This is executed last` কে আউটপুট স্ক্রিনে দেখা যাচ্ছে।  \n",
    "   "
   ]
  },
  {
   "cell_type": "markdown",
   "metadata": {},
   "source": [
    "## এক্সেপশন রেইজ (তৈরি) করা  \n",
    "\n",
    "আগে আমরা দেখেছি কিভাবে পাইথন প্রয়োজনে নিজে থেকেই প্রোগ্রামে কিছু এক্সেপশন তৈরি করে। চাইলে ম্যানুয়ালি কোড লিখেও প্রোগ্রামের নির্দিষ্ট কোন যায়গায় এক্সেপশন রেইজ বা সহজ ভাবে বলতে গেলে এক্সেপশন তৈরি করা যায়। `raise` স্টেটমেন্ট ব্যবহার করে এভাবে কাস্টম এক্সেপশন তৈরি করা যায়। নিচের উদাহরণটি দেখি - \n",
    "\n",
    "```python\n",
    "print(\"Hello\")\n",
    "raise NameError('HiThere')\n",
    "```  \n",
    "\n",
    "আউটপুট, \n",
    "\n",
    "```python\n",
    "Hello\n",
    "Traceback (most recent call last):\n",
    "  File \"<stdin>\", line 1, in <module>\n",
    "NameError: HiThere\n",
    "```  \n",
    "\n",
    "উপরের প্রোগ্রামের দ্বিতীয় লাইনে আমরা ম্যানুয়ালি একটি `NameError` টাইপের এক্সেপশন তৈরি করেছি যার কারনে পাইথন সাধারণভাবেই সেই এক্সেপশনটি থ্রো করেছে। \n",
    "\n",
    "উপরের মত এক্সেপশনের আর্গুমেন্ট (HiThere) সেট না করেও শুধু `NameError` এক্সপশন থ্রো করে যেত। যেমন নিচের মত - \n",
    "\n",
    "```python\n",
    "raise TypeError\n",
    "```  \n",
    "\n",
    "আউটপুট, \n",
    "\n",
    "```python\n",
    "Traceback (most recent call last):\n",
    "  File \"<stdin>\", line 1, in <module>\n",
    "TypeError\n",
    "```  \n",
    "\n",
    "`raise` এর একটি মজার ব্যবহার দেখবো নিচের উদাহরণে,   \n",
    "\n",
    "```python\n",
    "try:\n",
    "\tnum = 5 / 0\n",
    "except:\n",
    "\tprint(\"Custom message about an error!\")\n",
    "\traise\n",
    "```  \n",
    "\n",
    "আউটপুট, \n",
    "\n",
    "```python\n",
    "Custom message about an error!\n",
    "Traceback (most recent call last):\n",
    "  File \"/Users/nuhil/Desktop/Test.py\", line 2, in <module>\n",
    "    num = 5 / 0\n",
    "ZeroDivisionError: integer division or modulo by zero\n",
    "```   \n",
    "\n",
    "খেয়াল করুন কি ঘটছে উপরের প্রোগ্রামে। খুব সহজেই বোঝা যাচ্ছে যে `try` ব্লকে একটি এক্সেপশন ঘটছে। এটাও বুঝতে পারছি যে সেটা `ZeroDivisionError` এক্সেপশন হতে পারে কারন শূন্য দিয়ে ৫ কে ভাগ করার চেষ্টা করা হয়েছে। কিন্তু আমরা `except` ব্লকে নির্দিষ্ট করে কোন এক্সেপশন ডিফাইন করে সেটা হ্যান্ডেল করছি না। তারপরেও শেষ নাগাদ পাইথন আমাদেরকে `ZeroDivisionError: integer division or modulo by zero` এক্সেপশন দেখাতে পারছে। এর কারন - আমরা `except` এর মধ্যে `raise` ব্যবহার করেছি। এভাবেও `raise` কে কাজে লাগিয়ে এর আগে ঘটে যাওয়া এক্সেপশনের টাইপ পেয়ে যেতে পারি।   \n"
   ]
  },
  {
   "cell_type": "markdown",
   "metadata": {},
   "source": [
    "## Assertions  \n",
    "\n",
    "পাইথনে assertion তথা স্যানিটি চেক এনাবেল বা ডিজ্যাবল করে প্রোগ্রাম টেস্টিং এর কাজ করা হয়। কিন্তু, স্যানিটি চেক (sanity-check) আসলে কি? খুব দ্রুত একটি স্টেটমেন্টকে পর্যবেক্ষণ করে সেটার ফলাফলের সত্যতা যাচাই করাকেই স্যানিটি চেক বলা হয়।  \n",
    "\n",
    "`assert` স্টেটমেন্ট ব্যবহার করে এই কুইক টেস্ট করা হয়। যখন পাইথন কোন প্রোগ্রামের যেকোনো যায়গায় এই `assert` স্টেটমেন্টটি পায় তখন সেটাকে দ্রুত যাচাই করে এবং স্টেটমেন্টটি সত্য হোক সেটা আশা করে। কিন্তু তা না হলে পাইথন `AssertionError` টাইপের এক্সেপশন থ্রো (তৈরি) করে। একটি উদাহরণ দেখি -  \n",
    "\n",
    "```python\n",
    "print(1)\n",
    "assert 2 + 2 == 4\n",
    "print(2)\n",
    "assert 1 + 1 == 3\n",
    "print(3)\n",
    "```   \n",
    "\n",
    "আউটপুট, \n",
    "\n",
    "```python\n",
    "1\n",
    "2\n",
    "Traceback (most recent call last):\n",
    "  File \"/Users/nuhil/Desktop/Test.py\", line 4, in <module>\n",
    "    assert 1 + 1 == 3\n",
    "AssertionError\n",
    "```   \n",
    "\n",
    "উপরের প্রোগ্রামের প্রথম প্রিন্ট স্টেটমেন্টের পর একটি assertion সেট করা হয়েছে। সেখানে একটি সাধারণ অ্যারিদম্যাটিক কন্ডিশন যাচাই করা হয়েছে `assert` ব্যবহার করে। সেই স্যানিটি চেকটি সত্য বা পাশ হয়েছে (২ আর ২ যোগ করলে ৪ হয়)। তাই, `print(2)` স্টেটমেন্ট কাজ করছে। এরপর আবার একটি স্যানিটি চেক সেট করা হয়েছে। কিন্তু, স্বাভাবিক ভাবেই সেটি সত্য নয় (১ আর ১ যোগ করে ৩ হয় না)। তাই পাইথন সেখানে একটি `AssertionError` এক্সেপশন থ্রো করেছে। আর তাই, এর পরে থাকা `print(3)` স্টেটমেন্টটি এক্সিকিউটও হয় নি।   \n",
    "\n",
    "সাধারণত প্রোগ্রামারগণ কোন একটি ফাংশনের ডেফিনেশনের শুরুতেই এরকম স্যানিটি চেক ব্যবহার করেন ইনপুট/আর্গুমেন্ট ডাটা চেক করার জন্য। আবার ফাংশন কল এর পরেও ব্যবহার করে থাকেন ফাংশনের আউটপুট ডাটা চেক করার জন্য।\n",
    "\n",
    "আরেকটি উদাহরণ,  \n",
    "\n",
    "```python\n",
    "def KelvinToFahrenheit(Temperature):\n",
    "   assert (Temperature >= 0),\"Colder than absolute zero!\"\n",
    "   return ((Temperature-273)*1.8)+32\n",
    "\n",
    "print(KelvinToFahrenheit(273))\n",
    "print(int(KelvinToFahrenheit(505.78)))\n",
    "print(KelvinToFahrenheit(-5))\n",
    "```   \n",
    "\n",
    "আউটপুট,  \n",
    "\n",
    "```python\n",
    "32.0\n",
    "451\n",
    "Traceback (most recent call last):\n",
    "  File \"/Users/nuhil/Desktop/Test.py\", line 7, in <module>\n",
    "    print KelvinToFahrenheit(-5)\n",
    "  File \"/Users/nuhil/Desktop/Test.py\", line 2, in KelvinToFahrenheit\n",
    "    assert (Temperature >= 0),\"Colder than absolute zero!\"\n",
    "AssertionError: Colder than absolute zero!\n",
    "```  \n",
    "> বলা বাহুল্য, অন্যান্য এক্সেপশনের মত এই এক্সেপশনকেও `try`, `except` দিয়ে হ্যান্ডেল করা যায়। \n",
    "\n"
   ]
  },
  {
   "cell_type": "code",
   "execution_count": null,
   "metadata": {},
   "outputs": [],
   "source": []
  }
 ],
 "metadata": {
  "kernelspec": {
   "display_name": "Python 3",
   "language": "python",
   "name": "python3"
  },
  "language_info": {
   "codemirror_mode": {
    "name": "ipython",
    "version": 3
   },
   "file_extension": ".py",
   "mimetype": "text/x-python",
   "name": "python",
   "nbconvert_exporter": "python",
   "pygments_lexer": "ipython3",
   "version": "3.7.0"
  }
 },
 "nbformat": 4,
 "nbformat_minor": 2
}
